Workbook
Name BASIC: 'Sample 1'!$E$2:$E$6

Sheet Cell Ref
A1: Cell References
A3: Objective:
A4: After completing this chapter, you will be able to know
A5: • Meaning and usage of cell references.
A6: • Type of cell references.
A7: • Usage of range names.
A9: Why Use Different Types of References?
A10: When we copy a reference from one cell to another, it gets updated automatically. Say, we have a reference in cell C1 as A1 and we copy the same to D1, it automatically updates itself to B1. Sometimes, we need to keep a part of the used cell references as constant. This can be done using different types of cell references.
A12: Types of Cell Reference:
A13: There are three types of cell references as mentioned below;
A14: 1) Relative cell references
A15: 2) Absolute cell references
... A58: d) A1

Sheet Sample A
B2: RELATIVE CELL REFERENCE
B3: EMPNO | C3: NAME | D3: DESG | E3: Branch | F3: Sales | G3: Incentive @ 10%
B4: 1 | C4: RAJ | D4: OFFICER | E4: Mumbai | F4: 5000 | G4: =F4*0.1 -> 500 | H4: =_xlfn.FORMULATEXT(G4) -> =F4*0.1
B5: 2 | C5: RAJESH | D5: CLERK | E5: Mumbai | F5: 3500 | G5: =F5*0.1 -> 350
B6: 3 | C6: ANAND | D6: CLERK | E6: Delhi | F6: 10500 | G6: =F6*0.1 -> 1050
B7: 4 | C7: RAJU | D7: CLERK | E7: Delhi | F7: 13200 | G7: =F7*0.1 -> 1320
B8: 5 | C8: HEMANT | D8: MANAGER | E8: Mumbai | F8: 9550 | G8: =F8*0.1 -> 955
B13: ABSOLUTE CELL REFERENCE | G13: 0.1
B14: EMPNO | C14: NAME | D14: DESG | E14: Branch | F14: Sales | G14: Incentive
B15: 1 | C15: RAJ | D15: OFFICER | E15: Mumbai | F15: 5000 | G15: =F15*$G$13 -> 500
B16: 2 | C16: RAJESH | D16: CLERK | E16: Mumbai | F16: 3500 | G16: =F16*$G$13 -> 350
B17: 3 | C17: ANAND | D17: MANAGER | E17: Delhi | F17: 10500 | G17: =F17*$G$13 -> 1050
B18: 4 | C18: RAJU | D18: CLERK | E18: Delhi | F18: 13200 | G18: =F18*$G$13 -> 1320
B19: 5 | C19: HEMANT | D19: MANAGER | E19: Mumbai | F19: 9550 | G19: =F19*$G$13 -> 955
B24: MIXED CELL REFERENCE | G24: 0.1 | H24: 0.2 | I24: 0.3 | J24: 0.4 | K24: 0.5
B25: EMPNO | C25: NAME | D25: DESG | E25: Branch | F25: Sales | G25: Incentive 1 | H25: Incentive 2 | I25: Incentive 3 | J25: Incentive 4 | K25: Incentive 5
B26: 1 | C26: RAJ | D26: OFFICER | E26: Mumbai | F26: 1000 | G26: =$F26*G$24 -> 100 | H26: =$F26*H$24 -> 200 | I26: =$F26*I$24 -> 300 | J26: =$F26*J$24 -> 400 | K26: =$F26*K$24 -> 500
B27: 2 | C27: RAJESH | D27: CLERK | E27: Mumbai | F27: 2000 | G27: =$F27*G$24 -> 200 | H27: =$F27*H$24 -> 400 | I27: =$F27*I$24 -> 600 | J27: =$F27*J$24 -> 800 | K27: =$F27*K$24 -> 1000
B28: 3 | C28: ANAND | D28: MANAGER | E28: Delhi | F28: 3000 | G28: =$F28*G$24 -> 300 | H28: =$F28*H$24 -> 600 | I28: =$F28*I$24 -> 900 | J28: =$F28*J$24 -> 1200 | K28: =$F28*K$24 -> 1500
B29: 4 | C29: RAJU | D29: CLERK | E29: Delhi | F29: 4000 | G29: =$F29*G$24 -> 400 | H29: =$F29*H$24 -> 800 | I29: =$F29*I$24 -> 1200 | J29: =$F29*J$24 -> 1600 | K29: =$F29*K$24 -> 2000
B30: 5 | C30: HEMANT | D30: MANAGER | E30: Mumbai | F30: 5000 | G30: =$F30*G$24 -> 500 | H30: =$F30*H$24 -> 1000 | I30: =$F30*I$24 -> 1500 | J30: =$F30*J$24 -> 2000 | K30: =$F30*K$24 -> 2500

Sheet Range Names
A1: Range Names
A3: Named Ranges
A4: Many a times, when we write formulas/functions, we need to select a range of cells. However, doing this can be time consuming. Excel allows us to use a cell or a group of cells by its name. eg. Sum(Basic) sounds much easier compared to sum(H2:H101).However to do this, first we would need to name the range H2:H10 as Basic.
A6: Creating a Named Range
A7: To name a range, we may use one of the following procedures (Try using the Sample 1 for practice)
A8: 1) Select the range (eg: H2:H101) and type the name (eg: Sal) in the name box
A9: 2) If you want to name the cells with the value in one of the cells, you may select the range along with the name, click on “Create from Selection” in the Formulas Tab, select one of the options and click Ok.
A10: 3) You may also create a named range by clicking on “Define name” in Formulas Tab. Write the name for the range in the name box , click on the refers to box, select the range you wish to name and click Ok.
A12: Editing or Deleting Named Ranges
A13: Sometimes we would need to rename or redefine a named range. This can be done from Formulas Tab. In the "Formulas" Tab, click “Name Manager”.
A15: To edit a named range, click on the Named Range that you want to edit and click on the Edit button. An Edit Name dialog box appears where you may rename or redefine the range name.
A17: To delete a range, select the range from the Name Manager list and click Delete.
A18: Tips: Press Ctrl + F3 to get a Name Manager dialog box

Sheet Sample 1
A1: EMPNO | B1: NAME | C1: DESG | D1: Branch | E1: BASIC
A2: 1 | B2: RAJ | C2: OFFICER | D2: Mumbai | E2: 5000
A3: 2 | B3: RAJESH | C3: CLERK | D3: Mumbai | E3: 3500
A4: 3 | B4: ANAND | C4: MANAGER | D4: Delhi | E4: 7000 | F4: ctrl+F3 -- to add name
A5: 4 | B5: RAJU | C5: CLERK | D5: Delhi | E5: 4000
A6: 5 | B6: HEMANT | C6: MANAGER | D6: Mumbai | E6: 8000
D9: grand total | E9: =SUM(BASIC) -> 27500
D10: avg | E10: =AVERAGE(BASIC) -> 5500
D11: max | E11: =MAX(BASIC) -> 8000
D12: min | E12: =MIN(BASIC) -> 3500
D13: countA | E13: =COUNTA(BASIC) -> 5

Sheet Array Formula
A1: Working with Formulas and Functions
A3: Using Formulas in a Worksheet
A4: Formulas are equations that perform calculations on values. A formula starts with an equal sign (=). It contains at least two operands and at least one operation. For example, the following formula multiplies 2 by 3 and adds 5 to the result.
A5: =5+2*3
A6: Operand in a formula can be functions, references or constants. Operators may be any arithmetic or logical operator.
A7: Note: Excel follows BODMAS rule to solve a formula when multiple operators are involved.
A9: Array Formulae
A10: Here we have quantity and price of five products (Sample 2). We need to find the Total Sales which is the result of adding together the product of quantity and price for all products. In a normal scenario we would individually calculate the amount for each product and add them to get the answer. However, to make things simpler we may also use Array Formulae.
A11: E.g. Select B8 and write sum (A2:A6*B2:B6) and press Ctrl + Shift + Enter key combination to fill the formula {=sum(A1:A3*B1:B3)} in the selected cell. This calculates quantity*price for all the products in the cell B8.
A12: Note: Curly Brackets ({}) around the formula indicates that it is applied to an array.
A14: Tips: From an empty cell, you may click on the fx symbol near the formula bar to see all the available functions in excel.
A16: The syntax of a function is as follows
... A23: Tips: You can use "Alt + =" key combination to get the sum function on your worksheet.

Sheet Sample 2
A1: S.No. | B1: Product | C1: Qty | D1: Price | E1: amount
A2: 1 | B2: Rice | C2: 120 | D2: 90 | E2: =C2*D2 -> 10800
A3: 2 | B3: Wheat | C3: 125 | D3: 85 | E3: =C3*D3 -> 10625
A4: 3 | B4: Onions | C4: 125 | D4: 60 | E4: =C4*D4 -> 7500
A5: 4 | B5: Potato | C5: 150 | D5: 45 | E5: =C5*D5 -> 6750
A6: 5 | B6: Dal | C6: 140 | D6: 35 | E6: =C6*D6 -> 4900
A7: 6 | B7: Maize | C7: 130 | D7: 42 | E7: =C7*D7 -> 5460
E8: =SUM(E2:E7) -> 46035 | G8: ctrl +shift+ enter
D11: {=SUM(C2:C7*D2:D7)} -> 46035

Sheet Dates
B3: Calculating Day / Month / Year | I3: Taking out Year / Month / Day | S3: Age in Years & Months
B4: Year | C4: Month | D4: Day | E4: Dates | I4: Date | J4: Year | K4: Month | L4: Day | M4: date fixed | S4: Employee | T4: Birthday | U4: Today | V4: Year | W4: Month | X4: days | Y4: Combined both Yr and Month
B5: 2003 | C5: 2 | D5: 17 | E5: =DATE(B5,C5,D5) -> 37669 | F5: =DATE(B5,C5,D5) | I5: 38330 | J5: =YEAR(I5) -> 2004 | K5: =MONTH(I5) -> 12 | L5: =DAY(I5) -> 9 | M5: =DATE(J5,K5,L5) -> 38330 | N5: =YEAR(AN5) | O5: =MONTH(AN5) | P5: =DAY(AN5) | S5: Fletcher | T5: 25292 | U5: =TODAY() -> 46251 | V5: =DATEDIF(T5,U5,"y") -> 57 | W5: =DATEDIF(T5,U5,"YM") -> 4 | X5: =DATEDIF(T5,U5,"MD") -> 18 | Y5: =S5&" is "&V5&" years "&W5 &" months and " &X5&" days old" -> Fletcher is 57 years 4 months and 18 days old | Z5: =DATEDIF(AX5,AY5,"Y") & " years and " & DATEDIF(AX5,AY5,"YM") & " months"
B6: 2001 | C6: 2 | D6: 28 | E6: =DATE(B6,C6,D6) -> 36950 | F6: =DATE(B6,C6,D6) | I6: 37590 | J6: =YEAR(I6) -> 2002 | K6: =MONTH(I6) -> 11 | L6: =DAY(I6) -> 30 | M6: =DATE(J6,K6,L6) -> 37590 | N6: =YEAR(AN6) | O6: =MONTH(AN6) | P6: =DAY(AN6) | S6: Stone | T6: 25295 | U6: =TODAY() -> 46251 | V6: =DATEDIF(T6,U6,"y") -> 57 | W6: =DATEDIF(T6,U6,"YM") -> 4 | X6: =DATEDIF(T6,U6,"MD") -> 15 | Y6: =S6&" is "&V6&" years "&W6 &" months and " &X6&" days old" -> Stone is 57 years 4 months and 15 days old | Z6: =DATEDIF(AX6,AY6,"Y") & " years and " & DATEDIF(AX6,AY6,"YM") & " months"
B7: 2002 | C7: 5 | D7: 19 | E7: =DATE(B7,C7,D7) -> 37395 | F7: =DATE(B7,C7,D7) | I7: 37773 | J7: =YEAR(I7) -> 2003 | K7: =MONTH(I7) -> 6 | L7: =DAY(I7) -> 1 | M7: =DATE(J7,K7,L7) -> 37773 | N7: =YEAR(AN7) | O7: =MONTH(AN7) | P7: =DAY(AN7) | S7: Kerry | T7: 20713 | U7: =TODAY() -> 46251 | V7: =DATEDIF(T7,U7,"y") -> 69 | W7: =DATEDIF(T7,U7,"YM") -> 11 | X7: =DATEDIF(T7,U7,"MD") -> 2 | Y7: =S7&" is "&V7&" years "&W7 &" months and " &X7&" days old" -> Kerry is 69 years 11 months and 2 days old | Z7: =DATEDIF(AX7,AY7,"Y") & " years and " & DATEDIF(AX7,AY7,"YM") & " months"
B8: 2000 | C8: 3 | D8: 30 | E8: =DATE(B8,C8,D8) -> 36615 | F8: =DATE(B8,C8,D8) | I8: january 1999 | J8: =YEAR(I8) -> 1999 | K8: =MONTH(I8) -> 1 | L8: =DAY(I8) -> 1 | M8: =DATE(J8,K8,L8) -> 36161 | N8: =YEAR(AN8) | O8: =MONTH(AN8) | P8: =DAY(AN8) | S8: Butler | T8: 26191 | U8: =TODAY() -> 46251 | V8: =DATEDIF(T8,U8,"y") -> 54 | W8: =DATEDIF(T8,U8,"YM") -> 11 | X8: =DATEDIF(T8,U8,"MD") -> 2 | Y8: =S8&" is "&V8&" years "&W8 &" months and " &X8&" days old" -> Butler is 54 years 11 months and 2 days old | Z8: =DATEDIF(AX8,AY8,"Y") & " years and " & DATEDIF(AX8,AY8,"YM") & " months"
B9: 2003 | C9: 10 | D9: 21 | E9: =DATE(B9,C9,D9) -> 37915 | F9: =DATE(B9,C9,D9) | I9: 12/2005 | J9: =YEAR(I9) -> 2005 | K9: =MONTH(I9) -> 12 | L9: =DAY(I9) -> 1 | M9: =DATE(J9,K9,L9) -> 38687 | N9: =YEAR(AN9) | O9: =MONTH(AN9) | P9: =DAY(AN9) | S9: Smith | T9: 28402 | U9: =TODAY() -> 46251 | V9: =DATEDIF(T9,U9,"y") -> 48 | W9: =DATEDIF(T9,U9,"YM") -> 10 | X9: =DATEDIF(T9,U9,"MD") -> 13 | Y9: =S9&" is "&V9&" years "&W9 &" months and " &X9&" days old" -> Smith is 48 years 10 months and 13 days old | Z9: =DATEDIF(AX9,AY9,"Y") & " years and " & DATEDIF(AX9,AY9,"YM") & " months"
B10: 2001 | C10: 4 | D10: 12 | E10: =DATE(B10,C10,D10) -> 36993 | F10: =DATE(B10,C10,D10) | I10: =TODAY() -> 46251 | J10: =YEAR(I10) -> 2026 | K10: =MONTH(I10) -> 8 | L10: =DAY(I10) -> 17 | M10: =DATE(J10,K10,L10) -> 46251 | N10: =YEAR(AN10) | O10: =MONTH(AN10) | P10: =DAY(AN10) | S10: Miller | T10: 22578 | U10: =TODAY() -> 46251 | V10: =DATEDIF(T10,U10,"y") -> 64 | W10: =DATEDIF(T10,U10,"YM") -> 9 | X10: =DATEDIF(T10,U10,"MD") -> 24 | Y10: =S10&" is "&V10&" years "&W10 &" months and " &X10&" days old" -> Miller is 64 years 9 months and 24 days old | Z10: =DATEDIF(AX10,AY10,"Y") & " years and " & DATEDIF(AX10,AY10,"YM") & " months"
B11: 2004 | C11: 1 | D11: 2 | E11: =DATE(B11,C11,D11) -> 37988 | F11: =DATE(B11,C11,D11) | I11: 38297 | J11: =YEAR(I11) -> 2004 | K11: =MONTH(I11) -> 11 | L11: =DAY(I11) -> 6 | M11: =DATE(J11,K11,L11) -> 38297 | N11: =YEAR(AN11) | O11: =MONTH(AN11) | P11: =DAY(AN11) | S11: Brown | T11: 24421 | U11: =TODAY() -> 46251 | V11: =DATEDIF(T11,U11,"y") -> 59 | W11: =DATEDIF(T11,U11,"YM") -> 9 | X11: =DATEDIF(T11,U11,"MD") -> 7 | Y11: =S11&" is "&V11&" years "&W11 &" months and " &X11&" days old" -> Brown is 59 years 9 months and 7 days old | Z11: =DATEDIF(AX11,AY11,"Y") & " years and " & DATEDIF(AX11,AY11,"YM") & " months"
B12: 2004 | C12: 3 | D12: 21 | E12: =DATE(B12,C12,D12) -> 38067 | F12: =DATE(B12,C12,D12) | I12: 38751 | J12: =YEAR(I12) -> 2006 | K12: =MONTH(I12) -> 2 | L12: =DAY(I12) -> 3 | M12: =DATE(J12,K12,L12) -> 38751 | N12: =YEAR(AN12) | O12: =MONTH(AN12) | P12: =DAY(AN12) | S12: Wall | T12: 27717 | U12: =TODAY() -> 46251 | V12: =DATEDIF(T12,U12,"y") -> 50 | W12: =DATEDIF(T12,U12,"YM") -> 8 | X12: =DATEDIF(T12,U12,"MD") -> 29 | Y12: =S12&" is "&V12&" years "&W12 &" months and " &X12&" days old" -> Wall is 50 years 8 months and 29 days old | Z12: =DATEDIF(AX12,AY12,"Y") & " years and " & DATEDIF(AX12,AY12,"YM") & " months"
B13: 2003 | C13: 12 | D13: 28 | E13: =DATE(B13,C13,D13) -> 37983 | F13: =DATE(B13,C13,D13) | I13: 37876 | J13: =YEAR(I13) -> 2003 | K13: =MONTH(I13) -> 9 | L13: =DAY(I13) -> 12 | M13: =DATE(J13,K13,L13) -> 37876 | N13: =YEAR(AN13) | O13: =MONTH(AN13) | P13: =DAY(AN13) | S13: Denver | T13: 20049 | U13: =TODAY() -> 46251 | V13: =DATEDIF(T13,U13,"y") -> 71 | W13: =DATEDIF(T13,U13,"YM") -> 8 | X13: =DATEDIF(T13,U13,"MD") -> 27 | Y13: =S13&" is "&V13&" years "&W13 &" months and " &X13&" days old" -> Denver is 71 years 8 months and 27 days old | Z13: =DATEDIF(AX13,AY13,"Y") & " years and " & DATEDIF(AX13,AY13,"YM") & " months"
U17: & Function | V17: Used to combine or Concatenate any 2 or more cells or any text that you want to add | W17: Used to combine or Concatenate any 2 or more cells or any text that you want to add | Y17: Used to combine or Concatenate any 2 or more cells or any text that you want to add
B18: `
U19: datedif --- to get date differenec
J20: jan | U20: (=date 1, date2,"y") | W20: year
U21: (=date 1, date2,"m") | W21: month
U22: (=date 1, date2,"ym") | W22: year and month old

Sheet If Functions
A1: Working with Formulas and Functions
A3: IF function
A4: In Chapter 2, we have seen how to calculate the income heads like HRA and DA. The formula we saw was the same for the entire database. However, sometimes we need to decide the formula to apply in a cell according to certain conditions. For example, incentives may be calculated according to the department. This is where conditional functions like “IF” come in to the picture.
A5: You can use the IF function to evaluate a condition. The IF function returns different values depending on whether the condition is true or false. The syntax for the IF function is:
A7: If(logical_test, [Value_if_true], [Value_if_false])
A8: The first argument is the condition that you want the function to evaluate. The second argument is the value to be returned if the condition is true and the third argument is the value to be returned if the condition is false. Second and third parameters are optional.
A10: Example
A11: Suppose you want to calculate HRA based on designation of the employees, if Designation is Manager then HRA is1000 or else 500. Then the function code will be as follows:
A12: =if (C2="Manager", 1000, 500)
A14: Sample 3
A15: As given in Sample 3, above function calculates HRA as 1000 for Managers and 500 for others.
A17: Nested IF
... A74: If(and(not(department="Sales"),not(department="admin")),10%*salary,0)

Sheet Sample 11
A1: 0
L2: IF Func | M2: IF Func | N2: Nested IF | O2: IF with AND | P2: IF with OR | Q2: IF with NOT | R2: IF with NOT & with AND
B3: Emp. ID | C3: Name | D3: State | E3: Metro / Non Metro | F3: Designation | G3: Department | H3: BASIC | I3: HRA | J3: DA | L3: HRA_1 | M3: DA_1 | N3: TAX | O3: INCENTIVE | P3: HRA_2 | Q3: INCENTIVE_1 | R3: INCENTIVE_2 | S3: total
B4: G-101 | C4: Raj | D4: Uttrakhand | E4: Non Metro | F4: Manager | G4: Finance | H4: 18000 | I4: 9000 | J4: 900 | L4: =IF(E4="Metro",0.5*H4,0.4*H4) -> 7200 | M4: =IF(F4="Manager",0.25*H4,0.1*H4) -> 4500 | N4: =IF(H4<=25000,0.05*(H4),IF(H4<=45000,0.1*(H4),IF(H4<=60000,0.2*(H4),IF(H4<=80000,0.3*(H4),0.4*(H4))))) -> 900 | O4: =IF(AND(D4="Delhi",G4="Sales"),0.1*H4,0) -> 0 | P4: =IF(OR(G4="Sales",G4="Marketing",G4="HRD"),0.5*H4,0.3*H4) -> 5400 | Q4: =IF(NOT(G4="Marketing"),0.1*H4,) -> 1800 | R4: =IF(AND(NOT(G4="Sales"),NOT(G4="Admin")),0.1*H4,) -> 1800 | S4: =SUM(L4:R4) -> 21600
B5: G-102 | C5: Kiran | D5: Assam | E5: Non Metro | F5: Assistant Manager | G5: Marketing | H5: 13000 | I5: 6500 | J5: 650 | L5: =IF(E5="Metro",0.5*H5,0.4*H5) -> 5200 | M5: =IF(F5="Manager",0.25*H5,0.1*H5) -> 1300 | N5: =IF(H5<=25000,0.05*(H5),IF(H5<=45000,0.1*(H5),IF(H5<=60000,0.2*(H5),IF(H5<=80000,0.3*(H5),0.4*(H5))))) -> 650 | O5: =IF(AND(D5="Delhi",G5="Sales"),0.1*H5,0) -> 0 | P5: =IF(OR(G5="Sales",G5="Marketing",G5="HRD"),0.5*H5,0.3*H5) -> 6500 | Q5: =IF(NOT(G5="Marketing"),0.1*H5,) -> 0 | R5: =IF(AND(NOT(G5="Sales"),NOT(G5="Admin")),0.1*H5,) -> 1300 | S5: =SUM(L5:R5) -> 14950
B6: G-103 | C6: Shruti | D6: Delhi | E6: Metro | F6: Manager | G6: Sales | H6: 16500 | I6: 8250 | J6: 825 | L6: =IF(E6="Metro",0.5*H6,0.4*H6) -> 8250 | M6: =IF(F6="Manager",0.25*H6,0.1*H6) -> 4125 | N6: =IF(H6<=25000,0.05*(H6),IF(H6<=45000,0.1*(H6),IF(H6<=60000,0.2*(H6),IF(H6<=80000,0.3*(H6),0.4*(H6))))) -> 825 | O6: =IF(AND(D6="Delhi",G6="Sales"),0.1*H6,0) -> 1650 | P6: =IF(OR(G6="Sales",G6="Marketing",G6="HRD"),0.5*H6,0.3*H6) -> 8250 | Q6: =IF(NOT(G6="Marketing"),0.1*H6,) -> 1650 | R6: =IF(AND(NOT(G6="Sales"),NOT(G6="Admin")),0.1*H6,) -> 0 | S6: =SUM(L6:R6) -> 24750
B7: G-104 | C7: Ram | D7: Rajasthan | E7: Non Metro | F7: Executive | G7: HRD | H7: 8000 | I7: 4000 | J7: 400 | L7: =IF(E7="Metro",0.5*H7,0.4*H7) -> 3200 | M7: =IF(F7="Manager",0.25*H7,0.1*H7) -> 800 | N7: =IF(H7<=25000,0.05*(H7),IF(H7<=45000,0.1*(H7),IF(H7<=60000,0.2*(H7),IF(H7<=80000,0.3*(H7),0.4*(H7))))) -> 400 | O7: =IF(AND(D7="Delhi",G7="Sales"),0.1*H7,0) -> 0 | P7: =IF(OR(G7="Sales",G7="Marketing",G7="HRD"),0.5*H7,0.3*H7) -> 4000 | Q7: =IF(NOT(G7="Marketing"),0.1*H7,) -> 800 | R7: =IF(AND(NOT(G7="Sales"),NOT(G7="Admin")),0.1*H7,) -> 800 | S7: =SUM(L7:R7) -> 10000
B8: G-105 | C8: Inder | D8: Hyderabad | E8: Metro | F8: GM | G8: Admin | H8: 55000 | I8: 27500 | J8: 2750 | L8: =IF(E8="Metro",0.5*H8,0.4*H8) -> 27500 | M8: =IF(F8="Manager",0.25*H8,0.1*H8) -> 5500 | N8: =IF(H8<=25000,0.05*(H8),IF(H8<=45000,0.1*(H8),IF(H8<=60000,0.2*(H8),IF(H8<=80000,0.3*(H8),0.4*(H8))))) -> 11000 | O8: =IF(AND(D8="Delhi",G8="Sales"),0.1*H8,0) -> 0 | P8: =IF(OR(G8="Sales",G8="Marketing",G8="HRD"),0.5*H8,0.3*H8) -> 16500 | Q8: =IF(NOT(G8="Marketing"),0.1*H8,) -> 5500 | R8: =IF(AND(NOT(G8="Sales"),NOT(G8="Admin")),0.1*H8,) -> 0 | S8: =SUM(L8:R8) -> 66000
B9: G-106 | C9: Shailen | D9: Maharashtra | E9: Metro | F9: Vice President | G9: Marketing | H9: 72000 | I9: 36000 | J9: 3600 | L9: =IF(E9="Metro",0.5*H9,0.4*H9) -> 36000 | M9: =IF(F9="Manager",0.25*H9,0.1*H9) -> 7200 | N9: =IF(H9<=25000,0.05*(H9),IF(H9<=45000,0.1*(H9),IF(H9<=60000,0.2*(H9),IF(H9<=80000,0.3*(H9),0.4*(H9))))) -> 21600 | O9: =IF(AND(D9="Delhi",G9="Sales"),0.1*H9,0) -> 0 | P9: =IF(OR(G9="Sales",G9="Marketing",G9="HRD"),0.5*H9,0.3*H9) -> 36000 | Q9: =IF(NOT(G9="Marketing"),0.1*H9,) -> 0 | R9: =IF(AND(NOT(G9="Sales"),NOT(G9="Admin")),0.1*H9,) -> 7200 | S9: =SUM(L9:R9) -> 108000
B10: G-107 | C10: Goldy | D10: Uttar Pradesh | E10: Non Metro | F10: AGM | G10: HRD | H10: 40000 | I10: 20000 | J10: 2000 | L10: =IF(E10="Metro",0.5*H10,0.4*H10) -> 16000 | M10: =IF(F10="Manager",0.25*H10,0.1*H10) -> 4000 | N10: =IF(H10<=25000,0.05*(H10),IF(H10<=45000,0.1*(H10),IF(H10<=60000,0.2*(H10),IF(H10<=80000,0.3*(H10),0.4*(H10))))) -> 4000 | O10: =IF(AND(D10="Delhi",G10="Sales"),0.1*H10,0) -> 0 | P10: =IF(OR(G10="Sales",G10="Marketing",G10="HRD"),0.5*H10,0.3*H10) -> 20000 | Q10: =IF(NOT(G10="Marketing"),0.1*H10,) -> 4000 | R10: =IF(AND(NOT(G10="Sales"),NOT(G10="Admin")),0.1*H10,) -> 4000 | S10: =SUM(L10:R10) -> 52000
B11: G-108 | C11: Arpan | D11: Delhi | E11: Metro | F11: Manager | G11: Sales | H11: 15900 | I11: 7950 | J11: 795 | L11: =IF(E11="Metro",0.5*H11,0.4*H11) -> 7950 | M11: =IF(F11="Manager",0.25*H11,0.1*H11) -> 3975 | N11: =IF(H11<=25000,0.05*(H11),IF(H11<=45000,0.1*(H11),IF(H11<=60000,0.2*(H11),IF(H11<=80000,0.3*(H11),0.4*(H11))))) -> 795 | O11: =IF(AND(D11="Delhi",G11="Sales"),0.1*H11,0) -> 1590 | P11: =IF(OR(G11="Sales",G11="Marketing",G11="HRD"),0.5*H11,0.3*H11) -> 7950 | Q11: =IF(NOT(G11="Marketing"),0.1*H11,) -> 1590 | R11: =IF(AND(NOT(G11="Sales"),NOT(G11="Admin")),0.1*H11,) -> 0 | S11: =SUM(L11:R11) -> 23850
B12: G-109 | C12: Golu | D12: Tamil Nadu | E12: Metro | F12: President | G12: Admin | H12: 91000 | I12: 45500 | J12: 4550 | L12: =IF(E12="Metro",0.5*H12,0.4*H12) -> 45500 | M12: =IF(F12="Manager",0.25*H12,0.1*H12) -> 9100 | N12: =IF(H12<=25000,0.05*(H12),IF(H12<=45000,0.1*(H12),IF(H12<=60000,0.2*(H12),IF(H12<=80000,0.3*(H12),0.4*(H12))))) -> 36400 | O12: =IF(AND(D12="Delhi",G12="Sales"),0.1*H12,0) -> 0 | P12: =IF(OR(G12="Sales",G12="Marketing",G12="HRD"),0.5*H12,0.3*H12) -> 27300 | Q12: =IF(NOT(G12="Marketing"),0.1*H12,) -> 9100 | R12: =IF(AND(NOT(G12="Sales"),NOT(G12="Admin")),0.1*H12,) -> 0 | S12: =SUM(L12:R12) -> 127400
B13: G-110 | C13: Kailash | D13: Delhi | E13: Metro | F13: GM | G13: Finance | H13: 60500 | I13: 30250 | J13: 3025 | L13: =IF(E13="Metro",0.5*H13,0.4*H13) -> 30250 | M13: =IF(F13="Manager",0.25*H13,0.1*H13) -> 6050 | N13: =IF(H13<=25000,0.05*(H13),IF(H13<=45000,0.1*(H13),IF(H13<=60000,0.2*(H13),IF(H13<=80000,0.3*(H13),0.4*(H13))))) -> 18150 | O13: =IF(AND(D13="Delhi",G13="Sales"),0.1*H13,0) -> 0 | P13: =IF(OR(G13="Sales",G13="Marketing",G13="HRD"),0.5*H13,0.3*H13) -> 18150 | Q13: =IF(NOT(G13="Marketing"),0.1*H13,) -> 6050 | R13: =IF(AND(NOT(G13="Sales"),NOT(G13="Admin")),0.1*H13,) -> 6050 | S13: =SUM(L13:R13) -> 84700
B14: G-111 | C14: Amitabh | D14: Hyderabad | E14: Non Metro | F14: Executive | G14: Sales | H14: 7000 | I14: 3500 | J14: 350 | L14: =IF(E14="Metro",0.5*H14,0.4*H14) -> 2800 | M14: =IF(F14="Manager",0.25*H14,0.1*H14) -> 700 | N14: =IF(H14<=25000,0.05*(H14),IF(H14<=45000,0.1*(H14),IF(H14<=60000,0.2*(H14),IF(H14<=80000,0.3*(H14),0.4*(H14))))) -> 350 | O14: =IF(AND(D14="Delhi",G14="Sales"),0.1*H14,0) -> 0 | P14: =IF(OR(G14="Sales",G14="Marketing",G14="HRD"),0.5*H14,0.3*H14) -> 3500 | Q14: =IF(NOT(G14="Marketing"),0.1*H14,) -> 700 | R14: =IF(AND(NOT(G14="Sales"),NOT(G14="Admin")),0.1*H14,) -> 0 | S14: =SUM(L14:R14) -> 8050
B15: G-112 | C15: Raj Kapoor | D15: Maharashtra | E15: Metro | F15: Manager | G15: CSD | H15: 15000 | I15: 7500 | J15: 750 | L15: =IF(E15="Metro",0.5*H15,0.4*H15) -> 7500 | M15: =IF(F15="Manager",0.25*H15,0.1*H15) -> 3750 | N15: =IF(H15<=25000,0.05*(H15),IF(H15<=45000,0.1*(H15),IF(H15<=60000,0.2*(H15),IF(H15<=80000,0.3*(H15),0.4*(H15))))) -> 750 | O15: =IF(AND(D15="Delhi",G15="Sales"),0.1*H15,0) -> 0 | P15: =IF(OR(G15="Sales",G15="Marketing",G15="HRD"),0.5*H15,0.3*H15) -> 4500 | Q15: =IF(NOT(G15="Marketing"),0.1*H15,) -> 1500 | R15: =IF(AND(NOT(G15="Sales"),NOT(G15="Admin")),0.1*H15,) -> 1500 | S15: =SUM(L15:R15) -> 19500
B16: Grand Total | H16: =SUM(H4:H15) -> 411900 | I16: =SUM(I4:I15) -> 205950 | J16: =SUM(J4:J15) -> 20595 | L16: =SUM(L4:L15) -> 197350 | M16: =SUM(M4:M15) -> 51000 | N16: =SUM(N4:N15) -> 95820 | O16: =SUM(O4:O15) -> 3240 | P16: =SUM(P4:P15) -> 158050 | Q16: =SUM(Q4:Q15) -> 32690 | R16: =SUM(R4:R15) -> 22650
B18: Eg.1 | C18: IF Function
C19: Calculate HRA_1 - based on State that an employee belongs to, if employee is from Metro City then HRA is 50% of Basic salary otherwise 40% of Basic
B21: Eg.1 | C21: IF Function
C22: Calculate DA_1 - based on Designation of the employee, if employee is a Manager then DA will be 25% of Basic otherwise 10%
B24: Eg.2 | C24: Nested IF
C25: Calculate Tax - if the Gross Salary <=25,000 then tax is 5%, if salary is from 25,001-45,000 then Tax will be 10%, if salary is from 45,001-60,000 then Tax will be 20%, if salary is from 60,001-80,000 then Tax will be 30%, otherwise 40%
D26: <=25000 | E26: 0.05
D27: 25001-45000 | E27: 0.1
D28: 45001-60000 | E28: 0.2
D29: 60001-80000 | E29: 0.3
D30: >80000 | E30: 0.4
B32: Eg.3 | C32: IF with AND
C33: Calculate Incentive - If we need to give 10% of basic salary as incentive to every one working in “Sales” department and “Delhi” State.
B35: Eg.4 | C35: IF with OR
C36: Calculate HRA_2 - If the employee is in Sales, Marketing or Hrd, then hra is 50% of Basic salary otherwise, it is 30% of Basic salary
B38: Eg.5 | C38: IF with NOT
C39: Calculate Incentive_1 - If we need to give an 10 % incentive to everyone except people working in the “Marketing” department
B41: Eg. 6 | C41: IF with NOT with AND
C42: Calculate Incentive_2 , If you need to give an 10% incentive to everyone except people from the Sales and Admin department
B44: Eg. 7 | C44: Nested IF
C45: Suppose you want to assign letter grades to numbers referenced by the name Average Score. See the following table Below
C47: If Average Score is | D47: Then return | G47: Score | H47: Grade
C48: Greater than 89 | D48: A | G48: 55 | H48: =IF(G48<60,"F",IF(G48<70,"D",IF(G48<80,"C",IF(G48<90,"B","A")))) -> F
C49: From 80 to 89 | D49: B | G49: 89 | H49: =IF(G49<60,"F",IF(G49<70,"D",IF(G49<80,"C",IF(G49<90,"B","A")))) -> B
...

Sheet Vlookup & HLookup
A1: Working with Formulas and Functions
A3: Lookup Functions
A4: Sometimes, we need to search for a value in a database based on a lookup value. For example, given Employee Id, how can I look up the incentive value from some other sheet or some other file? In such scenarios, depending on the source database, we may use one of the following lookup functions.
A5: 1) V-lookup (If the database is vertical )
A6: 2) H-lookup (If the database is horizontal )
A8: V-lookup
A9: If we need to the get the value of a column from some other file or sheet based on a common field, you may use Vlookup. V-lookup is a function that searches for a value (lookup value) in the leftmost column of a given database (table array)and returns a value in the same row from a column you specify.
A11: Syntax:
A12: VLOOKUP(lookup_value,table_array,col_index_num,range_lookup)
A13: You can write this function using Built-in Function Arguments dialog-box. Click on Formulas Tab and search in the Lookup & Reference category for Vlookup. Click on Vlookup and you will get a Function Arguments dialog box.
A15: Lookup_value is the value to be found in the first column of the table. It is the value that you are looking for. Lookup_value can be a value, a reference or a text string.
A17: Table_array is the table of information in which data is looked up. It is the source database. Use a reference to a range or a range name.
... A80: In the emp_inf example, if we need to make the vlookup more dynamic using the column headers, we may use match with vlookup. Here the match looks for the labels on each field in the header of salary database and returns the position of the column dynamically.

Sheet Sample 5
A1: Name of Emp | B1: Region | C1: Department | D1: Basic | E1: HRA | F1: DA | G1: Gross Salary | H1: TDS | I1: Net Sal | J1: Designation
A2: Raj | B2: North | C2: Finance | D2: 4700 | E2: =D2*50% -> 2350 | F2: =(D2+E2)/2 -> 3525 | G2: =SUM(D2:F2) -> 10575 | H2: =G2*10% -> 1057.5 | I2: =G2-H2 -> 9517.5 | J2: Manager
A3: Kiran | B3: South | C3: Marketing | D3: 8700 | E3: =D3*50% -> 4350 | F3: =(D3+E3)/2 -> 6525 | G3: =SUM(D3:F3) -> 19575 | H3: =G3*10% -> 1957.5 | I3: =G3-H3 -> 17617.5 | J3: Assistant Manager
A4: vs | B4: North | C4: Sales | D4: 10800 | E4: =D4*50% -> 5400 | F4: =(D4+E4)/2 -> 8100 | G4: =SUM(D4:F4) -> 24300 | H4: =G4*10% -> 2430 | I4: =G4-H4 -> 21870 | J4: Manager
A5: Ram | B5: East | C5: Marketing | D5: 4500 | E5: =D5*50% -> 2250 | F5: =(D5+E5)/2 -> 3375 | G5: =SUM(D5:F5) -> 10125 | H5: =G5*10% -> 1012.5 | I5: =G5-H5 -> 9112.5 | J5: Executive
A6: Inder | B6: South | C6: Finance | D6: 8800 | E6: =D6*50% -> 4400 | F6: =(D6+E6)/2 -> 6600 | G6: =SUM(D6:F6) -> 19800 | H6: =G6*10% -> 1980 | I6: =G6-H6 -> 17820 | J6: Assistant Manager
A7: Shailen | B7: West | C7: Sales | D7: 7800 | E7: =D7*50% -> 3900 | F7: =(D7+E7)/2 -> 5850 | G7: =SUM(D7:F7) -> 17550 | H7: =G7*10% -> 1755 | I7: =G7-H7 -> 15795 | J7: Executive
L9: Name of Emp | M9: Raj | N9: Kiran | O9: vs | P9: Ram | Q9: Inder | R9: Shailen
L10: Region | M10: North | N10: South | O10: North | P10: East | Q10: South | R10: West
L11: Department | M11: Finance | N11: Marketing | O11: Sales | P11: Marketing | Q11: Finance | R11: Sales
L12: Basic | M12: 4700 | N12: 8700 | O12: 10800 | P12: 4500 | Q12: 8800 | R12: 7800
L13: HRA | M13: =M12*50% -> 2350 | N13: =N12*50% -> 4350 | O13: =O12*50% -> 5400 | P13: =P12*50% -> 2250 | Q13: =Q12*50% -> 4400 | R13: =R12*50% -> 3900
L14: DA | M14: =(M12+M13)/2 -> 3525 | N14: =(N12+N13)/2 -> 6525 | O14: =(O12+O13)/2 -> 8100 | P14: =(P12+P13)/2 -> 3375 | Q14: =(Q12+Q13)/2 -> 6600 | R14: =(R12+R13)/2 -> 5850
L15: Gross Salary | M15: =SUM(M12:M14) -> 10575 | N15: =SUM(N12:N14) -> 19575 | O15: =SUM(O12:O14) -> 24300 | P15: =SUM(P12:P14) -> 10125 | Q15: =SUM(Q12:Q14) -> 19800 | R15: =SUM(R12:R14) -> 17550
L16: TDS | M16: =M15*10% -> 1057.5 | N16: =N15*10% -> 1957.5 | O16: =O15*10% -> 2430 | P16: =P15*10% -> 1012.5 | Q16: =Q15*10% -> 1980 | R16: =R15*10% -> 1755
L17: Net Sal | M17: =M15-M16 -> 9517.5 | N17: =N15-N16 -> 17617.5 | O17: =O15-O16 -> 21870 | P17: =P15-P16 -> 9112.5 | Q17: =Q15-Q16 -> 17820 | R17: =R15-R16 -> 15795
L18: Designation | M18: Manager | N18: Assistant Manager | O18: Manager | P18: Executive | Q18: Assistant Manager | R18: Executive

Sheet Exer1
I1: Remove #n/a error | K1: If error
A2: S.No. | B2: Name of Employee | C2: DOJ | D2: Designation | E2: Department | F2: Gross Salary | G2: Vlookup | H2: Hlookup | I2: IFERROR | J2: Vlookup with column | K2: Vlookup with column
A3: 1 | B3: Inder | C3: 41546 | D3: Assistant Manager | E3: Finance | F3: 19800 | G3: =VLOOKUP(B3,'Sample 5'!$A$1:$J$7,4,FALSE) -> 8800 | H3: =HLOOKUP(B3,'Sample 5'!$L$9:$R$18,8,FALSE) -> 1980 | I3: =IFERROR(G3,0) -> 8800 | J3: =VLOOKUP(B3,'Sample 5'!A:J,4,FALSE) -> 8800
A4: 2 | B4: Kiran | C4: 43716 | D4: Assistant Manager | E4: Marketing | F4: 19575 | G4: =VLOOKUP(B4,'Sample 5'!$A$1:$J$7,4,FALSE) -> 8700 | H4: =HLOOKUP(B4,'Sample 5'!$L$9:$R$18,8,FALSE) -> 1957.5 | I4: =IFERROR(G4,0) -> 8700 | J4: =VLOOKUP(B4,'Sample 5'!A:J,4,FALSE) -> 8700
A5: 3 | B5: Raj | C5: 42126 | D5: Manager | E5: Finance | F5: 10575 | G5: =VLOOKUP(B5,'Sample 5'!$A$1:$J$7,4,FALSE) -> 4700 | H5: =HLOOKUP(B5,'Sample 5'!$L$9:$R$18,8,FALSE) -> 1057.5 | I5: =IFERROR(G5,0) -> 4700 | J5: =VLOOKUP(B5,'Sample 5'!A:J,4,FALSE) -> 4700
A6: 4 | B6: Ram | C6: 43243 | D6: Executive | E6: Marketing | F6: 10125 | G6: =VLOOKUP(B6,'Sample 5'!$A$1:$J$7,4,FALSE) -> 4500 | H6: =HLOOKUP(B6,'Sample 5'!$L$9:$R$18,8,FALSE) -> 1012.5 | I6: =IFERROR(G6,0) -> 4500 | J6: =VLOOKUP(B6,'Sample 5'!A:J,4,FALSE) -> 4500
A7: 5 | B7: Shailen | C7: 42771 | D7: Executive | E7: Sales | F7: 17550 | G7: =VLOOKUP(B7,'Sample 5'!$A$1:$J$7,4,FALSE) -> 7800 | H7: =HLOOKUP(B7,'Sample 5'!$L$9:$R$18,8,FALSE) -> 1755 | I7: =IFERROR(G7,0) -> 7800 | J7: =VLOOKUP(B7,'Sample 5'!A:J,4,FALSE) -> 7800 | S7: 0- exact value false
A8: 6 | B8: Shruti | C8: 41654 | D8: Manager | E8: Sales | F8: 24300 | G8: =VLOOKUP(B8,'Sample 5'!$A$1:$J$7,4,FALSE) -> #N/A | H8: =HLOOKUP(B8,'Sample 5'!$L$9:$R$18,8,FALSE) -> #N/A | I8: =IFERROR(G8,0) -> 0 | J8: =VLOOKUP(B8,'Sample 5'!A:J,4,FALSE) -> #N/A | S8: 1- true approx value
G9: =SUM(G3:G8) -> #N/A | H9: =SUM(H3:H8) -> #N/A | I9: =SUM(I3:I8) -> 34500 | J9: =SUM(J3:J8) -> #N/A | K9: =SUM(K3:K8) -> 0

Sheet Vlookup_Exercise
B1: Vlookup Exercise
B3: Ex. 1 | H3: Ex. 2
B4: Character | C4: Show | E4: Character | F4: Show | H4: Student | I4: Grade | J4: Letter Grade | L4: No. Grade | M4: Letter Grade
B5: Carlton Lassiter | C5: =VLOOKUP(B5,$E$4:$F$52,2,0) -> Psych | E5: Maddie Hayes | F5: Moonlighting | H5: Russ Geller | I5: 98 | J5: =VLOOKUP(I5,$L$4:$M$17,2,TRUE) -> A+ | L5: 0 | M5: F
B6: Dale Cooper | C6: =VLOOKUP(B6,$E$4:$F$52,2,0) -> Twin Peaks | E6: Sam Malone | F6: Cheers | H6: Sheldon Cooper | I6: 79 | J6: =VLOOKUP(I6,$L$4:$M$17,2,TRUE) -> C+ | L6: 60 | M6: D-
B7: David Addison | C7: =VLOOKUP(B7,$E$4:$F$52,2,0) -> Moonlighting | E7: David Addison | F7: Moonlighting | H7: Dexter Morgan | I7: 72 | J7: =VLOOKUP(I7,$L$4:$M$17,2,TRUE) -> C- | L7: 64 | M7: D
B8: Dexter Morgan | C8: =VLOOKUP(B8,$E$4:$F$52,2,0) -> Dexter | E8: Adrian Monk | F8: Monk | H8: Red Forman | I8: 93 | J8: =VLOOKUP(I8,$L$4:$M$17,2,TRUE) -> A- | L8: 67 | M8: D+
B9: Dr. Elliot Reid | C9: =VLOOKUP(B9,$E$4:$F$52,2,0) -> Scrubs | E9: Jeff Greene | F9: Curb Your Enthusiasm | H9: Harold T. Stone | I9: 64 | J9: =VLOOKUP(I9,$L$4:$M$17,2,TRUE) -> D | L9: 70 | M9: C-
B10: Dr. Gregory House | C10: =VLOOKUP(B10,$E$4:$F$52,2,0) -> House, M.D. | E10: Norm Peterson | F10: Cheers | H10: Shawn Spencer | I10: 92 | J10: =VLOOKUP(I10,$L$4:$M$17,2,TRUE) -> A- | L10: 74 | M10: C
B11: Edmund Blackadder | C11: =VLOOKUP(B11,$E$4:$F$52,2,0) -> Blackadder | E11: Matt Saracen | F11: Friday Night Lights | H11: Jim Ignatowski | I11: 70 | J11: =VLOOKUP(I11,$L$4:$M$17,2,TRUE) -> C- | L11: 77 | M11: C+
B12: Eric Cartman | C12: =VLOOKUP(B12,$E$4:$F$52,2,0) -> South Park | E12: Barney Stinson | F12: How I Met Your Mother | H12: John Locke | I12: 91 | J12: =VLOOKUP(I12,$L$4:$M$17,2,TRUE) -> A- | L12: 80 | M12: B-
B13: Fox Mulder | C13: =VLOOKUP(B13,$E$4:$F$52,2,0) -> The X Files | E13: Bill McNeal | F13: NewsRadio | H13: Bill McNeal | I13: 96 | J13: =VLOOKUP(I13,$L$4:$M$17,2,TRUE) -> A | L13: 84 | M13: B
B14: George Costanza | C14: =VLOOKUP(B14,$E$4:$F$52,2,0) -> Seinfeld | E14: Harry Solomon | F14: 3rd Rock from the Sun | H14: Adrian Monk | I14: 68 | J14: =VLOOKUP(I14,$L$4:$M$17,2,TRUE) -> D+ | L14: 87 | M14: B+
B15: Gloria Pritchett | C15: =VLOOKUP(B15,$E$4:$F$52,2,0) -> Modern Family | E15: Kim Bauer | F15: 24 | H15: Lynette Scavo | I15: 51 | J15: =VLOOKUP(I15,$L$4:$M$17,2,TRUE) -> F | L15: 90 | M15: A-
B16: Hank Hill | C16: =VLOOKUP(B16,$E$4:$F$52,2,0) -> King of the Hill | E16: Gloria Pritchett | F16: Modern Family | H16: Robert Barone | I16: 94 | J16: =VLOOKUP(I16,$L$4:$M$17,2,TRUE) -> A | L16: 94 | M16: A
B17: Harold T. Stone | C17: =VLOOKUP(B17,$E$4:$F$52,2,0) -> Night Court | E17: Jack Bauer | F17: 24 | H17: Sam Malone | I17: 74 | J17: =VLOOKUP(I17,$L$4:$M$17,2,TRUE) -> C | L17: 97 | M17: A+
B18: Harry Solomon | C18: =VLOOKUP(B18,$E$4:$F$52,2,0) -> 3rd Rock from the Sun | E18: George Costanza | F18: Seinfeld | H18: Homer Simpson | I18: 53 | J18: =VLOOKUP(I18,$L$4:$M$17,2,TRUE) -> F
B19: Homer Simpson | C19: =VLOOKUP(B19,$E$4:$F$52,2,0) -> The Simpsons | E19: Phil Dunphy | F19: Modern Family | H19: Dr. Elliot Reid | I19: 89 | J19: =VLOOKUP(I19,$L$4:$M$17,2,TRUE) -> B+
B20: Hurley Reyes | C20: =VLOOKUP(B20,$E$4:$F$52,2,0) -> Lost | E20: Lynette Scavo | F20: Desperate Housewives | H20: Bob Kelso | I20: 55 | J20: =VLOOKUP(I20,$L$4:$M$17,2,TRUE) -> F
B21: Jack Bauer | C21: =VLOOKUP(B21,$E$4:$F$52,2,0) -> 24 | E21: Hank Hill | F21: King of the Hill | H21: Dr. Gregory House | I21: 79 | J21: =VLOOKUP(I21,$L$4:$M$17,2,TRUE) -> C+
B22: Jack Malone | C22: =VLOOKUP(B22,$E$4:$F$52,2,0) -> Without A Trace | E22: Veronica Mars | F22: Veronica Mars | H22: Dale Cooper | I22: 98 | J22: =VLOOKUP(I22,$L$4:$M$17,2,TRUE) -> A+
B23: Jeff Greene | C23: =VLOOKUP(B23,$E$4:$F$52,2,0) -> Curb Your Enthusiasm | E23: Walter White | F23: Breaking Bad | H23: Hurley Reyes | I23: 95 | J23: =VLOOKUP(I23,$L$4:$M$17,2,TRUE) -> A
B24: Jim Ignatowski | C24: =VLOOKUP(B24,$E$4:$F$52,2,0) -> Taxi | E24: Shawn Spencer | F24: Psych | H24: Lorelai Gilmore | I24: 63 | J24: =VLOOKUP(I24,$L$4:$M$17,2,TRUE) -> D-
B25: John Locke | C25: =VLOOKUP(B25,$E$4:$F$52,2,0) -> Lost | E25: Bob Kelso | F25: Scrubs | H25: Harry Solomon | I25: 57 | J25: =VLOOKUP(I25,$L$4:$M$17,2,TRUE) -> F
B26: Kim Bauer | C26: =VLOOKUP(B26,$E$4:$F$52,2,0) -> 24 | E26: Monica Bing | F26: Friends | H26: Hank Hill | I26: 91 | J26: =VLOOKUP(I26,$L$4:$M$17,2,TRUE) -> A-
B27: Liz Lemon | C27: =VLOOKUP(B27,$E$4:$F$52,2,0) -> 30 Rock | E27: Harold T. Stone | F27: Night Court | H27: Carlton Lassiter | I27: 95 | J27: =VLOOKUP(I27,$L$4:$M$17,2,TRUE) -> A
B28: Lorelai Gilmore | C28: =VLOOKUP(B28,$E$4:$F$52,2,0) -> Gilmore Girls | E28: Carlton Lassiter | F28: Psych | H28: Barney Stinson | I28: 97 | J28: =VLOOKUP(I28,$L$4:$M$17,2,TRUE) -> A+
B29: Lynette Scavo | C29: =VLOOKUP(B29,$E$4:$F$52,2,0) -> Desperate Housewives | E29: Eric Cartman | F29: South Park | H29: Walter White | I29: 97 | J29: =VLOOKUP(I29,$L$4:$M$17,2,TRUE) -> A+
... B37: Phillip J. Fry | C37: =VLOOKUP(B37,$E$4:$F$52,2,0) -> Futurama | E37: John Locke | F37: Lost | H37: Jeff Greene | I37: 56 | J37: =VLOOKUP(I37,$L$4:$M$17,2,TRUE) -> F
E38: Jim Ignatowski | F38: Taxi | H38: Norm Peterson | I38: 52 | J38: =VLOOKUP(I38,$L$4:$M$17,2,TRUE) -> F
E39: Homer Simpson | F39: The Simpsons | H39: Eric Cartman | I39: 94 | J39: =VLOOKUP(I39,$L$4:$M$17,2,TRUE) -> A
E40: Edmund Blackadder | F40: Blackadder | H40: Natalie Teeger | I40: 55 | J40: =VLOOKUP(I40,$L$4:$M$17,2,TRUE) -> F
E41: Carlton Banks | F41: The Fresh Prince of Bel-Air | H41: David Addison | I41: 54 | J41: =VLOOKUP(I41,$L$4:$M$17,2,TRUE) -> F
E42: Dr. Elliot Reid | F42: Scrubs
E43: Russ Geller | F43: Friends
E44: Dale Cooper | F44: Twin Peaks
E45: Natalie Teeger | F45: Monk
E46: Dr. Gregory House | F46: House, M.D.
E47: Dexter Morgan | F47: Dexter
E48: Hurley Reyes | F48: Lost
...

Sheet Pivot Tables
A1: Pivot Tables
A3: This chapter would help you learn how to
A4: • Create Pivot Tables.
A5: • Make different reports using Pivot Tables.
A6: • Use advanced features of Pivot Tables.
A7: A Pivot Table is an interactive worksheet based table that quickly summarizes large amounts of data using the format and calculation methods you choose. It is called a Pivot Table because you can rotate its row and column headings around the core data area to give you different views of the source data. As source data changes, you can update a pivot table. It resides on a worksheet thus; you can integrate a Pivot Table into a larger worksheet model using standard formulas. You can use a PivotTable to analyze data in an Excel workbook or from an external database such as Microsoft Access or SQL Server.
A9: Examining PivotTables
A10: The data on which a PivotTable is based is called the Source Data. Each column represents a field or category of information, which you can assign to different parts of the PivotTable to determine how the data is arranged. You can add four types of fields. The fields are explained in the following table:
A12: Description | B12: Field
A13: Filters the summarized data in the PivotTable. If you select an item in the report filter, the view of the PivotTable changes to display only the summarized data associated with that item. For example, if Region is a report filter, you can display the summarized data for North, West, or all regions. | B13: Report Filter
A14: Displays the items in a field as row labels. For example given below, the row labels are values in the Quarter field, which means that the table shows one row for each quarter. | B14: Row Labels
A15: Displays the items in a field as column labels. For example, given below, the column labels are values in the Product field, which means that the table shows one column for each product. | B15: Column Labels
A16: Contains the summarized data. These fields usually contain numeric data, such as sales and inventory. The area where the data itself appears is called the data area. | B16: ? Values
A18: Exer 9
A19: 1) Select any cell in a data range that includes a heading for each column in the top row.
A20: 2) Activate the Insert tab.
A21: 3) In the Tables group, click the PivotTable button, or click the PivotTable list and select PivotTable to open the Create PivotTable dialog box.
A22: 4) In the Table/Range box, select the range that contains the data to be used in the PivotTable.
A23: 5) Select the location for the PivotTable. You can place the PivotTable in a new or existing worksheet. Click OK to create the PivotTable.
A25: Add fields
A26: You can add fields to a PivotTable to specify the data you want to display. The fields of the source data appears in the "PivotTable Field List" task pane.
A27: To add fields, drag the relevant field from the top of the PivotTable Field List to one of the four areas at the bottom. You can add more than one field to an area, and you do not need to add all fields to the table. To display data and not just headings, you need to place at least one field in the ? Values area.
A28: After the fields are in place, you can filter the information that appears in the table by selecting from the Filter columns, Filter rows, or report filter lists. For example, you can show all data values, or restrict the PivotTable to summarizing only a couple of them.
A30: Format a PivotTable report
A31: You can modify the format of a PivotTable by using styles and the Field Settings dialog box. You can use styles to format an entire PivotTable in one step. You can use the Field Settings dialog box to change number formats, specify how data is summarized, and show or hide data.
... A62: Tips: Click anywhere inside the pivot table and press alt F1 Keycombination to create a pivot chart. F11 creates the chart on a new sheet.

Sheet Exer9
A1: Name of Emp | B1: Region | C1: Department | D1: Designation | E1: Salary | F1: HRA | G1: DA | H1: Gross Total | I1: TDS | J1: Net Sal
A2: Raj | B2: North | C2: Finance | D2: Manager | E2: 4789 | F2: 2394.5 | G2: 3591.75 | H2: 10775.25 | I2: 1077.525 | J2: 9697.725
A3: Kiran | B3: South | C3: Marketing | D3: Assistant Manager | E3: 4700 | F3: 2350 | G3: 3525 | H3: 10575 | I3: 1057.5 | J3: 9517.5
A4: Shruti | B4: North | C4: Sales | D4: Manager | E4: 11980 | F4: 5990 | G4: 8985 | H4: 26955 | I4: 2695.5 | J4: 24259.5
A5: Ram | B5: East | C5: HRD | D5: Executive | E5: 6500 | F5: 3250 | G5: 4875 | H5: 14625 | I5: 1462.5 | J5: 13162.5
A6: Inder | B6: South | C6: Admin | D6: GM | E6: 5689 | F6: 2844.5 | G6: 4266.75 | H6: 12800.25 | I6: 1280.025 | J6: 11520.225
A7: Shailen | B7: West | C7: Sales | D7: Vice President | E7: 5798 | F7: 2899 | G7: 4348.5 | H7: 13045.5 | I7: 1304.55 | J7: 11740.95
A8: Goldy | B8: South | C8: HRD | D8: AGM | E8: 6789 | F8: 3394.5 | G8: 5091.75 | H8: 15275.25 | I8: 1527.525 | J8: 13747.725
A9: Arpan | B9: North | C9: Sales | D9: Manager | E9: 13980 | F9: 6990 | G9: 10485 | H9: 31455 | I9: 3145.5 | J9: 28309.5
A10: Golu | B10: East | C10: Admin | D10: President | E10: 5467 | F10: 2733.5 | G10: 4100.25 | H10: 12300.75 | I10: 1230.075 | J10: 11070.675
A11: Kailash | B11: South | C11: Finance | D11: GM | E11: 8978 | F11: 4489 | G11: 6733.5 | H11: 20200.5 | I11: 2020.05 | J11: 18180.45
A12: Amitabh | B12: West | C12: Sales | D12: Executive | E12: 7890 | F12: 3945 | G12: 5917.5 | H12: 17752.5 | I12: 1775.25 | J12: 15977.25
A13: Raj Kapoor | B13: South | C13: CSD | D13: Assistant Manager | E13: 9900 | F13: 4950 | G13: 7425 | H13: 22275 | I13: 2227.5 | J13: 20047.5
... A16: Diljeet | B16: South | C16: Finance | D16: AGM | E16: 12034 | F16: 6017 | G16: 9025.5 | H16: 27076.5 | I16: 2707.65 | J16: 24368.85

Sheet Types of Charts
B2: AREA CHARTS
B3: Less Items | G3: Too Many Items
C4: Computers | D4: Furniture | E4: Office Supplies | H4: Computers | I4: Furniture | J4: Office Supplies | K4: Electrical Supplies | L4: Software | M4: Day Planners | N4: Health & Safety | O4: Productivity Tools
B5: 2017 | C5: 2000 | D5: 600 | E5: 75 | G5: 2017 | H5: 1400 | I5: 1200 | J5: 300 | K5: 1800 | L5: 1200 | M5: 900 | N5: 400 | O5: 32
B6: 2018 | C6: 3300 | D6: 760 | E6: 85 | G6: 2018 | H6: 2200 | I6: 1100 | J6: 590 | K6: 1700 | L6: 500 | M6: 800 | N6: 300 | O6: 25
B7: 2019 | C7: 4100 | D7: 500 | E7: 225 | G7: 2019 | H7: 2100 | I7: 500 | J7: 125 | K7: 1900 | L7: 900 | M7: 800 | N7: 200 | O7: 75
B8: 2020 | C8: 3000 | D8: 750 | E8: 123 | G8: 2020 | H8: 3000 | I8: 750 | J8: 123 | K8: 2200 | L8: 1250 | M8: 900 | N8: 200 | O8: 80
B28: BAR CHARTS
F30: Region | G30: Jan | H30: Feb | I30: Mar | J30: Apr | K30: May
F31: US | G31: 20000 | H31: 22000 | I31: 19000 | J31: 23000 | K31: 24000
F32: Europe | G32: 14500 | H32: 14600 | I32: 14500 | J32: 14450 | K32: 16000
F33: Asia | G33: 26000 | H33: 17000 | I33: 18000 | J33: 28000 | K33: 30000
F34: South America | G34: 5000 | H34: 3000 | I34: 3500 | J34: 6000 | K34: 2000
B53: Period | C53: Stock 1 | D53: Stock 2 | K53: Period | L53: Stock 1 | M53: Stock 2
B54: 42370 | C54: 0.19 | D54: -0.05 | K54: Month 1 - 2016 | L54: 0.09 | M54: -0.01
B55: 42371 | C55: 0.07 | D55: 0.2 | K55: Month 2 - 2016 | L55: 0.06 | M55: 0.09
B56: 42372 | C56: 0.07 | D56: 0.03 | K56: Month 3 - 2016 | L56: 0.03 | M56: -0.01
B57: 42373 | C57: -0.11 | D57: -0.01 | K57: Month 4 - 2016 | L57: -0.01 | M57: 0.1
B58: 42374 | C58: 0.09 | D58: 0.19 | K58: Month 5 - 2016 | L58: 0.05 | M58: 0.1
B59: 42375 | C59: 0.02 | D59: 0.03 | K59: Month 6 - 2016 | L59: 0.11 | M59: 0.09
B60: 42376 | C60: -0.14 | D60: 0.15 | K60: Month 7 - 2016 | L60: -0.01 | M60: -0.01
B61: 42377 | C61: 0.03 | D61: 0.09 | K61: Month 8 - 2016 | L61: 0.09 | M61: -0.02
B62: 42378 | C62: -0.06 | D62: 0.05 | K62: Month 9 - 2016 | L62: -0.01 | M62: 0.09
B63: 42379 | C63: -0.01 | D63: 0.15 | K63: Month 10 - 2016 | L63: 0.04 | M63: 0.04
B64: 42380 | C64: 0.06 | D64: 0.09 | K64: Month 11 - 2016 | L64: 0.12 | M64: 0.1
B65: 42381 | C65: 0.04 | D65: 0.17 | K65: Month 12 - 2016 | L65: 0.01 | M65: 0
... B77: 42393 | C77: -0.07 | D77: 0.15 | K77: Month 12 - 2017 | L77: 0.11 | M77: 0.04
B78: 42394 | C78: 0.11 | D78: 0.05
B79: 42395 | C79: -0.1 | D79: -0.14
B80: 42396 | C80: -0.04 | D80: 0.01
B81: 42397 | C81: 0.06 | D81: 0.2
B82: 42398 | C82: 0 | D82: 0.1
B83: 42399 | C83: -0.12 | D83: -0.09
B84: 42400 | C84: 0.01 | D84: -0.11
B85: 42401 | C85: -0.03 | D85: 0.15
B86: 42402 | C86: 0.2 | D86: 0.11
B87: 42403 | C87: -0.05 | D87: -0.01
B88: 42404 | C88: 0.04 | D88: 0.13
B89: 42405 | C89: -0.09 | D89: -0.11
... B784: 43100 | C784: 0.08 | D784: -0.09
...

Sheet Exer 9a
A1: Category | B1: Product | C1: Sales | D1: Quarter
A2: Beverages | B2: Chai | C2: 705.6 | D2: Qtr 1
A3: Beverages | B3: Chai | C3: 878.4 | D3: Qtr 2 | F3: Eg - 1 | G3: Which Category has the higest Sales?
A4: Beverages | B4: Chai | C4: 1174.5 | D4: Qtr 3 | F4: Eg - 2 | G4: Which Quarter has registered the lowest sales?
A5: Beverages | B5: Chai | C5: 2128.5 | D5: Qtr 4 | F5: Eg - 3 | G5: Which product has the highest sales?
A6: Beverages | B6: Chang | C6: 2720.8 | D6: Qtr 1 | F6: Eg - 4 | G6: Show the percentage wise breakup of Catergory and Quarter.
A7: Beverages | B7: Chang | C7: 228 | D7: Qtr 2 | F7: Eg - 5 | G7: Present the Overall percentage breakup of Quarter wise & Category wise sales in Pie chart.
A8: Beverages | B8: Chang | C8: 2061.5 | D8: Qtr 3
A9: Beverages | B9: Chang | C9: 2028.25 | D9: Qtr 4
A10: Beverages | B10: Chartreuse verte | C10: 590.4 | D10: Qtr 1
A11: Beverages | B11: Chartreuse verte | C11: 360 | D11: Qtr 2
A12: Beverages | B12: Chartreuse verte | C12: 1100.7 | D12: Qtr 3
A13: Beverages | B13: Chartreuse verte | C13: 2424.6 | D13: Qtr 4
A14: Beverages | B14: Côte de Blaye | C14: 25127.36 | D14: Qtr 1
A15: Beverages | B15: Côte de Blaye | C15: 12806.1 | D15: Qtr 2
A16: Beverages | B16: Côte de Blaye | C16: 7312.12 | D16: Qtr 3
A17: Beverages | B17: Côte de Blaye | C17: 1317.5 | D17: Qtr 4
A18: Beverages | B18: Guaraná Fantástica | C18: 529.2 | D18: Qtr 1
A19: Beverages | B19: Guaraná Fantástica | C19: 467.55 | D19: Qtr 2
... A287: Seafood | B287: Spegesild | C287: 823.2 | D287: Qtr 4

Sheet What-if-analysis
A1: What-if-Analysis Tools
A3: This chapter tells you how to analyze data using
A4: • Goal Seek
A5: • Data Tables
A6: • Scenario Manager
A8: In situations where, you may have to use several different sets of values in one or more formulas to explore all the various results, manual interference may increase leading to errors. What-If Analysis tools can come to your rescue at such situations. There are 3 What-If Analysis tools in excel namely:
A10: 1) Goal-seek
A11: 2) Data-Tables
A12: 3) Scenario-Manager
A14: Goal Seek
A15: Suppose you have created a formula to calculate PMT based on the formula, you want to know the number of months you need to pay to complete the installment provided you pay x amount per month. For such kind of reverse analysis, you may use Goal Seek utility. This type of analysis involves changing the values in a worksheet and observing how these changes affect the results of the formulas. You use Goal Seek to solve problems that have one variable.
A16: The Goal Seek feature in Excel helps us to compute a value for the spreadsheet input that makes the value for the given formula match the goal you specify. Goal Seeking saves you from performing time consuming trial-and-error analysis.
... A118: Note: When sheet protection is activated, you can still add scenarios. However, you cannot edit or delete them unless the Prevent Changes check box is cleared.

Sheet Sample 10
B2: Goal Seek
B3: A | C3: B | D3: C
B4: 1 | C4: Loan Amount | D4: 5000000
B5: 2 | C5: Rate of Interest | D5: 0.095
B6: 3 | C6: Total no. of month to pay | D6: 240
B7: 4 | C7: EMI per month | D7: =PMT(D5/12,D6,-D4) -> 46606.559
B10: Question | C10: If EMI is Rs. 35000 then how much loan should be availed by this person

Sheet Solver
A1: Solver for Advanced Goal Seek
A3: Units Sold | C3: 458 | D3: INPUT
A4: Price per unit | C4: 4 | D4: INPUT
A5: Revenue | C5: =C3*C4 -> 1832
A8: Cost Per unit | C8: 1.5 | D8: INPUT
A9: Costs | C9: =C3*C8 -> 687
A11: Profit | C11: =C5-C9 -> 1145
A13: With Goal seek you can change only One cell and not the other cells data.
A15: For example :-
A16: You want to change the Units Sold and it must be rounded
A17: Price Per Unit cant go above Rs. 4 (i.e. <=4/-)
A18: Cost per unit must be below Rs. 1.50 (i.e. <=1.50/-)
A20: Solve a Complex Problem with Solver
A22: Project Name | B22: Prod Cost | C22: Fixed Cost | D22: Extra Cost | E22: Total costs
A23: Proj A | B23: 4200 | C23: 2000 | D23: 200 | E23: =B23+C23+D23 -> 6400
A24: Proj B | B24: 5300 | C24: 2000 | D24: 600 | E24: =B24+C24+D24 -> 7900
A25: Proj C | B25: 3200 | C25: 2000 | D25: 800 | E25: =B25+C25+D25 -> 6000
A26: Proj D | B26: 4000 | C26: 2000 | D26: 500 | E26: =B26+C26+D26 -> 6500
A27: Proj E | B27: 1000 | C27: 2000 | D27: 400 | E27: =B27+C27+D27 -> 3400
A28: Proj F | B28: 900 | C28: 2000 | D28: 300 | E28: =B28+C28+D28 -> 3200
A29: Proj G | B29: 6500 | C29: 2000 | D29: 200 | E29: =B29+C29+D29 -> 8700
A30: Proj H | B30: 7000 | C30: 2000 | D30: 600 | E30: =B30+C30+D30 -> 9600
A31: Proj I | B31: 6200 | C31: 2000 | D31: 800 | E31: =B31+C31+D31 -> 9000
C32: Total Costs | E32: =SUM(E23:E31) -> 60700
A34: Constraints
A35: Total Budget should not exceed | E35: 65000
A36: Extra costs should not exceed | E36: 1000
A37: Fixed costs need to reamain at | E37: 2000
A38: Total Proj Costs for each project should not exceed | E38: 9600

Sheet SUM IF & COUNT IF & SUM PROD
B2: SUM IF & COUNT IF & SUMPRODUCT

Sheet Exer12
B2: ID | C2: Empl Rcd# | D2: Name | E2: TYPE | F2: Earn Code | G2: Quantity ( in Hrs) | H2: Rpt Date | I2: DAY | K2: TYPE | L2: Countif | M2: Sumif
B3: 311587 | C3: 100 | D3: Smith,Jacob | E3: SP | F3: SIC | G3: 2 | H3: 40528 | I3: THURSDAY | K3: SP | T3: =COUNTIF($E$3:$E$215,K3)
B4: 645109 | C4: 125 | D4: Johnson,Michael | E4: SFFNR | F4: SIC | G4: 8 | H4: 40527 | I4: WEDNESDAY | K4: SFFNR
B5: 645109 | C5: 150 | D5: Johnson,Michael | E5: SFFNR | F5: SIC | G5: 8 | H5: 40528 | I5: THURSDAY | K5: SFAM
B6: 835119 | C6: 175 | D6: Jones,Matthew | E6: SFAM | F6: SIC | G6: 5 | H6: 40527 | I6: WEDNESDAY | K6: SFNRL
B7: 921565 | C7: 200 | D7: Jones,Matthew | E7: SFNRL | F7: SIC | G7: 8 | H7: 40528 | I7: THURSDAY | K7: SICK | T7: =SUMIF($E$3:$E$215,K3,$G$3:$G$215)
B8: 904174 | C8: 225 | D8: Brown,Daniel | E8: SP | F8: SIC | G8: 4 | H8: 40528 | I8: THURSDAY | L8: =SUM(L3:L7) -> 0 | M8: =SUM(M3:M7) -> 0
B9: 108501 | C9: 250 | D9: Davis,Christopher | E9: SFAM | F9: SIC | G9: 3.5 | H9: 40527 | I9: WEDNESDAY
B10: 806984 | C10: 275 | D10: Miller,Andrew | E10: SICK | F10: SIC | G10: 8 | H10: 40528 | I10: THURSDAY
B11: 605544 | C11: 300 | D11: Wilson,Ethan | E11: SFFNR | F11: SIC | G11: 8 | H11: 40527 | I11: WEDNESDAY | K11: DAY | L11: Countif | M11: Sumif
B12: 261528 | C12: 325 | D12: Moore,Joseph | E12: SICK | F12: SIC | G12: 8 | H12: 40527 | I12: WEDNESDAY | K12: MONDAY | T12: =COUNTIF($I$3:$I$215,K12)
B13: 261528 | C13: 350 | D13: Moore,Joseph | E13: SICK | F13: SIC | G13: 8 | H13: 40528 | I13: THURSDAY | K13: TUESDAY
B14: 682726 | C14: 375 | D14: Taylor,William | E14: SP | F14: SIC | G14: 1 | H14: 40527 | I14: WEDNESDAY | K14: WEDNESDAY
B15: 682726 | C15: 400 | D15: Taylor,William | E15: SP | F15: SIC | G15: 1.5 | H15: 40528 | I15: THURSDAY | K15: THURSDAY
B16: 268234 | C16: 425 | D16: Anderson,Anthony | E16: SP | F16: SIC | G16: 1.5 | H16: 40527 | I16: WEDNESDAY | K16: FRIDAY | T16: =SUMIF($I$3:$I$215,K12,$G$3:$G$215)
B17: 537900 | C17: 450 | D17: Thomas,David | E17: SP | F17: SIC | G17: 2 | H17: 40527 | I17: WEDNESDAY | L17: =SUM(L12:L16) -> 0 | M17: =SUM(M12:M16) -> 0
B18: 935382 | C18: 475 | D18: Jackson,Alexander | E18: SP | F18: SIC | G18: 3.5 | H18: 40527 | I18: WEDNESDAY
B19: 602526 | C19: 500 | D19: White,Nicholas | E19: SP | F19: SIC | G19: 2 | H19: 40527 | I19: WEDNESDAY | K19: COUNTIFS / SUMPRODUCT
B20: 624084 | C20: 525 | D20: Harris,Ryan | E20: SP | F20: SIC | G20: 1.25 | H20: 40528 | I20: THURSDAY
B21: 341458 | C21: 550 | D21: Martin,Tyler | E21: SICK | F21: SIC | G21: 8 | H21: 40528 | I21: THURSDAY | L21: Occurrences
B22: 674630 | C22: 575 | D22: Thompson,James | E22: SP | F22: SIC | G22: 2.75 | H22: 40528 | I22: THURSDAY | L22: MONDAY | M22: TUESDAY | N22: WEDNESDAY | O22: THURSDAY | P22: FRIDAY | Q22: Total
B23: 674630 | C23: 600 | D23: Thompson,James | E23: SFAM | F23: SIC | G23: 1 | H23: 40528 | I23: THURSDAY | K23: SP | Q23: =SUM(L23:P23) -> 0
B24: 752850 | C24: 625 | D24: Garcia,John | E24: SFAM | F24: SIC | G24: 1.25 | H24: 40527 | I24: WEDNESDAY | K24: SFFNR | Q24: =SUM(L24:P24) -> 0 | T24: =COUNTIFS($E$3:$E$215,$K23,$I$3:$I$215,L$22)
B25: 951321 | C25: 650 | D25: Martinez,Jonathan | E25: SP | F25: SIC | G25: 8.75 | H25: 40529 | I25: FRIDAY | K25: SFAM | Q25: =SUM(L25:P25) -> 0
B26: 311587 | C26: 675 | D26: Smith,Jacob | E26: SFNRL | F26: SIC | G26: 4 | H26: 40529 | I26: FRIDAY | K26: SFNRL | Q26: =SUM(L26:P26) -> 0
B27: 140990 | C27: 700 | D27: Robinson,Noah | E27: SP | F27: SIC | G27: 2 | H27: 40540 | I27: TUESDAY | K27: SICK | Q27: =SUM(L27:P27) -> 0
B28: 883669 | C28: 725 | D28: Clark,Brandon | E28: SICK | F28: SIC | G28: 4.75 | H28: 40534 | I28: WEDNESDAY | K28: Total | L28: =SUM(L23:L27) -> 0 | M28: =SUM(M23:M27) -> 0 | N28: =SUM(N23:N27) -> 0 | O28: =SUM(O23:O27) -> 0 | P28: =SUM(P23:P27) -> 0 | Q28: =SUM(L28:P28) -> 0 | T28: =SUMPRODUCT(($E$3:$E$215=$K36)*($I$3:$I$215='Sample 9'!L$35))
B29: 733760 | C29: 750 | D29: Rodriguez,Christian | E29: SP | F29: SIC | G29: 3.5 | H29: 40532 | I29: MONDAY
B30: 474941 | C30: 775 | D30: Lewis,Dylan | E30: SP | F30: SIC | G30: 2.5 | H30: 40534 | I30: WEDNESDAY
B31: 474941 | C31: 800 | D31: Lewis,Dylan | E31: SP | F31: SIC | G31: 1.5 | H31: 40540 | I31: TUESDAY
B32: 615307 | C32: 825 | D32: Lee,Samuel | E32: SP | F32: SIC | G32: 4 | H32: 40529 | I32: FRIDAY | K32: SUMIFS / SUMPRODUCT
B33: 144775 | C33: 850 | D33: Walker,Benjamin | E33: SP | F33: SIC | G33: 2 | H33: 40540 | I33: TUESDAY
B34: 54857 | C34: 875 | D34: Hall,Zachary | E34: SP | F34: SIC | G34: 1 | H34: 40533 | I34: TUESDAY | L34: Hours
B35: 969490 | C35: 900 | D35: Allen,Nathan | E35: SFAM | F35: SIC | G35: 3 | H35: 40533 | I35: TUESDAY | L35: MONDAY | M35: TUESDAY | N35: WEDNESDAY | O35: THURSDAY | P35: FRIDAY | Q35: Total
B36: 969490 | C36: 925 | D36: Allen,Nathan | E36: SICK | F36: SIC | G36: 8 | H36: 40534 | I36: WEDNESDAY | K36: SP | Q36: =SUM(L36:P36) -> 0 | T36: =SUMIFS($G$3:$G$215,$E$3:$E$215,$K36,$I$3:$I$215,L$35)
B37: 579919 | C37: 950 | D37: Young,Logan | E37: SICK | F37: SIC | G37: 2 | H37: 40534 | I37: WEDNESDAY | K37: SFFNR | Q37: =SUM(L37:P37) -> 0
B38: 599675 | C38: 975 | D38: Hernandez,Justin | E38: SP | F38: SIC | G38: 2 | H38: 40534 | I38: WEDNESDAY | K38: SFAM | Q38: =SUM(L38:P38) -> 0
B39: 625135 | C39: 1000 | D39: King,Gabriel | E39: SP | F39: SIC | G39: 1 | H39: 40540 | I39: TUESDAY | K39: SFNRL | Q39: =SUM(L39:P39) -> 0
B40: 664825 | C40: 1025 | D40: Wright,Jose | E40: SICK | F40: SIC | G40: 8 | H40: 40542 | I40: THURSDAY | K40: SICK | Q40: =SUM(L40:P40) -> 0 | T40: =SUMPRODUCT(($E$3:$E$215=$K36)*($I$3:$I$215=L$35)*($G$3:$G$215))
B41: 664825 | C41: 1050 | D41: Wright,Jose | E41: SICK | F41: SIC | G41: 6 | H41: 40541 | I41: WEDNESDAY | K41: Total | L41: =SUM(L36:L40) -> 0 | M41: =SUM(M36:M40) -> 0 | N41: =SUM(N36:N40) -> 0 | O41: =SUM(O36:O40) -> 0 | P41: =SUM(P36:P40) -> 0 | Q41: =SUM(L41:P41) -> 0
...

Sheet Final Exam
A1: Solve the below questions | B1: Final Assignment
A2: 1) Calculate DA for Officer 10%, Manager 15%, & Clerk 5% of Basic (using Vlookup). | B2: Salary statement for the month of April
A3: 2) Calculate HRA as following condition (using If condition) For Officer 1000, Manager 1500, Clerk 500 | B3: EMPNO | C3: NAME | D3: DESG | E3: Branch | F3: BASIC
A4: 3) Calculate Conveyance 10 % of Basic using (Range Name) | B4: 1 | C4: RAJ | D4: OFFICER | E4: Mumbai | F4: 5000
A5: 4) Calculate Gross [ie Basic + DA +HRA+CONV] | B5: 2 | C5: RAJESH | D5: CLERK | E5: Mumbai | F5: 3500
A6: 5) Calculate ESIC according to Slab-wise on Basic as follows(using Vlookup) | B6: 3 | C6: ANAND | D6: MANAGER | E6: Delhi | F6: 7000
A7: • From 0 - 1000 = 50 | B7: 4 | C7: RAJU | D7: CLERK | E7: Delhi | F7: 4000
A8: • 1001 - 3000 = 100 | B8: 5 | C8: HEMANT | D8: MANAGER | E8: Mumbai | F8: 8000
A9: • 3001 - 5000 = 250 | B9: 6 | C9: SANTOSH | D9: CLERK | E9: Delhi | F9: 3780
A10: • >5000 = 300 | B10: 7 | C10: BHAUMIK | D10: OFFICER | E10: Delhi | F10: 4200
A11: 6) Calculate Tax according to Slab-wise on Gross (using if function) | B11: 8 | C11: MANJIT | D11: OFFICER | E11: Mumbai | F11: 5000
A12: • i.e. <10000 = 0 | B12: 9 | C12: KAMAL | D12: OFFICER | E12: Delhi | F12: 3800
A13: • >10000 &<15000 = 750 | B13: 10 | C13: SONU | D13: CLERK | E13: Mumbai | F13: 2500
A14: • >15000 = 1500
A15: 7) Calculate P.F as 5 % on Basic Salary
A16: 8) Calculate Loan 2% of Gross
A17: 9) Calculate Net Salary ie [Gross-[ESIC+IT+PF+LOAN]]
A18: Make multiple copies of the Worksheet and solve the following questions in different sheets. Name the sheets with question number example answer to question number 10 would be solved in the worksheet name q10.
A19: 10) Create a Chart of Name, Basic, Gross & Net [Should be well formatted]
A20: 11) Sort your Records Desg wise. [ie Manager then officer and then clerk] [ Custom Sort]
A21: 12) Display only the records of Clerk & Manager [Using Auto Filter].
A22: 13) Display the Records of those people whose Net Salary is between 1000 –3000 and 6000-9000 and get the result on a new page [Using Advance Filter].
A23: 14) Get the total salary branch wise by subtotal [Using Subtotal Command].
A24: 15) Create a Pivot Report Branch wise, Designation wise Net Salary & count the No of Employee.
A25: 16) Freeze the Name column & the heading of the data. [Using Freeze Pane].
... A29: 20) Give Password to the File as Final.
